Workbook

Sheet Orders
A1: Order ID | B1: Customer ID | C1: Customer Country | D1: Order Datetime | E1: Order Source | F1: Sales POC | G1: Order Value | H1: OrderDate | I1: OrderTime | J1: OrderMonth | K1: OrderDay | L1: Outlier Check | M1: Age
A2: 1597 | B2: 856 | C2: USA | D2: 45275.035 | E2: Other | F2: Kwai Yu | G2: 412 | H2: =INT(D2) -> 45275 | I2: =MOD(D2,1) -> 0.034722222 | J2: =TEXT(D2,"mmmm") -> December | K2: =TEXT(D2,"dddd") -> Friday | L2: =IF(OR(G2>Answers!I17,G2<Answers!I18),"Outlier","Normal") -> Normal | M2: 59
A3: 2011 | B3: 525 | C3: India | D3: 45045.986 | E3: Whatsapp | F3: Paul Henriot | G3: 4551 | H3: =INT(D3) -> 45045 | I3: =MOD(D3,1) -> 0.98611111 | J3: =TEXT(D3,"mmmm") -> April | K3: =TEXT(D3,"dddd") -> Saturday | L3: =IF(OR(G3>Answers!I18,G3<Answers!I19),"Outlier","Normal") -> Outlier | M3: 20
A4: 2822 | B4: 1614 | C4: USA | D4: 45290.015 | E4: Whatsapp | F4: Daniel Da Cunha | G4: 3960 | H4: =INT(D4) -> 45290 | I4: =MOD(D4,1) -> 0.014583333 | J4: =TEXT(D4,"mmmm") -> December | K4: =TEXT(D4,"dddd") -> Saturday | L4: =IF(OR(G4>Answers!I19,G4<Answers!I20),"Outlier","Normal") -> Outlier | M4: 37
A5: 2889 | B5: 743 | C5: USA | D5: 45258.022 | E5: Whatsapp | F5: Julie Young | G5: 8397 | H5: =INT(D5) -> 45258 | I5: =MOD(D5,1) -> 0.021527778 | J5: =TEXT(D5,"mmmm") -> November | K5: =TEXT(D5,"dddd") -> Tuesday | L5: =IF(OR(G5>Answers!I20,G5<Answers!I21),"Outlier","Normal") -> Outlier | M5: 29
A6: 3971 | B6: 20 | C6: USA | D6: 45225.966 | E6: Website | F6: Julie Brown | G6: 5545 | H6: =INT(D6) -> 45225 | I6: =MOD(D6,1) -> 0.96597222 | J6: =TEXT(D6,"mmmm") -> October | K6: =TEXT(D6,"dddd") -> Thursday | L6: =IF(OR(G6>Answers!I21,G6<Answers!I22),"Outlier","Normal") -> Outlier | M6: 38
A7: 4111 | B7: 1367 | C7: Italy | D7: 44993.953 | E7: App | F7: Juri Hirano | G7: 7800 | H7: =INT(D7) -> 44993 | I7: =MOD(D7,1) -> 0.95277778 | J7: =TEXT(D7,"mmmm") -> March | K7: =TEXT(D7,"dddd") -> Wednesday | L7: =IF(OR(G7>Answers!I22,G7<Answers!I23),"Outlier","Normal") -> Outlier | M7: 25
A8: 4801 | B8: 945 | C8: France | D8: 44975.016 | E8: Other | F8: Martine Rance | G8: 4674 | H8: =INT(D8) -> 44975 | I8: =MOD(D8,1) -> 0.015972222 | J8: =TEXT(D8,"mmmm") -> February | K8: =TEXT(D8,"dddd") -> Saturday | L8: =IF(OR(G8>Answers!I23,G8<Answers!I24),"Outlier","Normal") -> Outlier | M8: 34
A9: 5719 | B9: 218 | C9: France | D9: 45253.049 | E9: Website | F9: Veysel Oeztan | G9: 5954 | H9: =INT(D9) -> 45253 | I9: =MOD(D9,1) -> 0.048611111 | J9: =TEXT(D9,"mmmm") -> November | K9: =TEXT(D9,"dddd") -> Thursday | L9: =IF(OR(G9>Answers!I24,G9<Answers!I25),"Outlier","Normal") -> Outlier | M9: 34
A10: 5846 | B10: 264 | C10: USA | D10: 45283.056 | E10: Website | F10: Julie Murphy | G10: 9887 | H10: =INT(D10) -> 45283 | I10: =MOD(D10,1) -> 0.055555556 | J10: =TEXT(D10,"mmmm") -> December | K10: =TEXT(D10,"dddd") -> Saturday | L10: =IF(OR(G10>Answers!I25,G10<Answers!I26),"Outlier","Normal") -> Outlier | M10: 46
A11: 7615 | B11: 566 | C11: USA | D11: 45233.99 | E11: Whatsapp | F11: Dominique Perrier | G11: 8303 | H11: =INT(D11) -> 45233 | I11: =MOD(D11,1) -> 0.99027778 | J11: =TEXT(D11,"mmmm") -> November | K11: =TEXT(D11,"dddd") -> Friday | L11: =IF(OR(G11>Answers!I26,G11<Answers!I27),"Outlier","Normal") -> Outlier | M11: 74
A12: 8568 | B12: 1414 | C12: USA | D12: 45133.008 | E12: App | F12: Peter Ferguson | G12: 8969 | H12: =INT(D12) -> 45133 | I12: =MOD(D12,1) -> 0.0076388889 | J12: =TEXT(D12,"mmmm") -> July | K12: =TEXT(D12,"dddd") -> Wednesday | L12: =IF(OR(G12>Answers!I27,G12<Answers!I28),"Outlier","Normal") -> Outlier | M12: 28
A13: 9339 | B13: 1681 | C13: Spain | D13: 45278.027 | E13: App | F13: Michael Frick | G13: 2782 | H13: =INT(D13) -> 45278 | I13: =MOD(D13,1) -> 0.027083333 | J13: =TEXT(D13,"mmmm") -> December | K13: =TEXT(D13,"dddd") -> Monday | L13: =IF(OR(G13>Answers!I28,G13<Answers!I29),"Outlier","Normal") -> Outlier | M13: 38
... A2501: 1682358 | B2501: 567 | C2501: Australia | D2501: 45012.972 | E2501: Website | F2501: Helen Bennett | G2501: 4540 | H2501: =INT(D2501) -> 45012 | I2501: =MOD(D2501,1) -> 0.97152778 | J2501: =TEXT(D2501,"mmmm") -> March | K2501: =TEXT(D2501,"dddd") -> Monday | L2501: =IF(OR(G2501>Answers!I2516,G2501<Answers!I2517),"Outlier","Normal") -> Outlier | M2501: 37

Sheet Customers
A1: Customer ID | B1: Customer Country | C1: Gender | D1: Age | E1: Category | F1: Outlier Check | G1: Age Group
A2: 1 | B2: France | C2: M | D2: 31 | E2: A | F2: =IF(OR(D2>Answers!L17,D2<Answers!L18),"Outlier","Normal") -> Normal | G2: =IF(D2<20,"<20", IF(D2<=30,"20-30", IF(D2<=40,"30-40","40-50"))) -> 30-40
A3: 2 | B3: Spain | C3: M | D3: 49 | E3: A | F3: =IF(OR(D3>Answers!L18,D3<Answers!L19),"Outlier","Normal") -> Outlier | G3: =IF(D3<20,"<20", IF(D3<=30,"20-30", IF(D3<=40,"30-40","40-50"))) -> 40-50
A4: 3 | B4: USA | C4: M | D4: 39 | E4: A | F4: =IF(OR(D4>Answers!L19,D4<Answers!L20),"Outlier","Normal") -> Outlier | G4: =IF(D4<20,"<20", IF(D4<=30,"20-30", IF(D4<=40,"30-40","40-50"))) -> 30-40
A5: 4 | B5: Australia | C5: M | D5: =ROUND(AVERAGE(D2:D4),0) -> 40 | E5: A | F5: =IF(OR(D5>Answers!L20,D5<Answers!L21),"Outlier","Normal") -> Outlier | G5: =IF(D5<20,"<20", IF(D5<=30,"20-30", IF(D5<=40,"30-40","40-50"))) -> 30-40
A6: 5 | B6: Denmark | C6: M | D6: 81 | E6: A | F6: =IF(OR(D6>Answers!L21,D6<Answers!L22),"Outlier","Normal") -> Outlier | G6: =IF(D6<20,"<20", IF(D6<=30,"20-30", IF(D6<=40,"30-40","40-50"))) -> 40-50
A7: 6 | B7: USA | C7: F | D7: 62 | E7: A | F7: =IF(OR(D7>Answers!L22,D7<Answers!L23),"Outlier","Normal") -> Outlier | G7: =IF(D7<20,"<20", IF(D7<=30,"20-30", IF(D7<=40,"30-40","40-50"))) -> 40-50
A8: 7 | B8: Singapore | C8: M | D8: 76 | E8: A | F8: =IF(OR(D8>Answers!L23,D8<Answers!L24),"Outlier","Normal") -> Outlier | G8: =IF(D8<20,"<20", IF(D8<=30,"20-30", IF(D8<=40,"30-40","40-50"))) -> 40-50
A9: 8 | B9: France | C9: F | D9: 70 | E9: A | F9: =IF(OR(D9>Answers!L24,D9<Answers!L25),"Outlier","Normal") -> Outlier | G9: =IF(D9<20,"<20", IF(D9<=30,"20-30", IF(D9<=40,"30-40","40-50"))) -> 40-50
A10: 9 | B10: France | C10: F | D10: 75 | E10: A | F10: =IF(OR(D10>Answers!L25,D10<Answers!L26),"Outlier","Normal") -> Outlier | G10: =IF(D10<20,"<20", IF(D10<=30,"20-30", IF(D10<=40,"30-40","40-50"))) -> 40-50
A11: 10 | B11: Norway | C11: F | D11: 32 | E11: A | F11: =IF(OR(D11>Answers!L26,D11<Answers!L27),"Outlier","Normal") -> Outlier | G11: =IF(D11<20,"<20", IF(D11<=30,"20-30", IF(D11<=40,"30-40","40-50"))) -> 30-40
A12: 11 | B12: USA | C12: F | D12: 82 | E12: A | F12: =IF(OR(D12>Answers!L27,D12<Answers!L28),"Outlier","Normal") -> Outlier | G12: =IF(D12<20,"<20", IF(D12<=30,"20-30", IF(D12<=40,"30-40","40-50"))) -> 40-50
A13: 12 | B13: Spain | C13: F | D13: 65 | E13: A | F13: =IF(OR(D13>Answers!L28,D13<Answers!L29),"Outlier","Normal") -> Outlier | G13: =IF(D13<20,"<20", IF(D13<=30,"20-30", IF(D13<=40,"30-40","40-50"))) -> 40-50
A14: 13 | B14: Spain | C14: F | D14: 84 | E14: A | F14: =IF(OR(D14>Answers!L29,D14<Answers!L30),"Outlier","Normal") -> Outlier | G14: =IF(D14<20,"<20", IF(D14<=30,"20-30", IF(D14<=40,"30-40","40-50"))) -> 40-50
A15: 14 | B15: Australia | C15: M | D15: 64 | E15: A | F15: =IF(OR(D15>Answers!L30,D15<Answers!L31),"Outlier","Normal") -> Outlier | G15: =IF(D15<20,"<20", IF(D15<=30,"20-30", IF(D15<=40,"30-40","40-50"))) -> 40-50
A16: 15 | B16: Germany | C16: F | D16: 48 | E16: A | F16: =IF(OR(D16>Answers!L31,D16<Answers!L32),"Outlier","Normal") -> Outlier | G16: =IF(D16<20,"<20", IF(D16<=30,"20-30", IF(D16<=40,"30-40","40-50"))) -> 40-50
A17: 16 | B17: Norway | C17: F | D17: 81 | E17: A | F17: =IF(OR(D17>Answers!L32,D17<Answers!L33),"Outlier","Normal") -> Outlier | G17: =IF(D17<20,"<20", IF(D17<=30,"20-30", IF(D17<=40,"30-40","40-50"))) -> 40-50
... A1260: 1259 | B1260: USA | C1260: M | D1260: 45 | E1260: C | F1260: =IF(OR(D1260>Answers!L1275,D1260<Answers!L1276),"Outlier","Normal") -> Outlier | G1260: =IF(D1260<20,"<20", IF(D1260<=30,"20-30", IF(D1260<=40,"30-40","40-50"))) -> 40-50
A1261: 1260 | B1261: France | C1261: M | D1261: =ROUND(AVERAGE(D1258:D1260),0) -> 67 | E1261: C | F1261: =IF(OR(D1261>Answers!L1276,D1261<Answers!L1277),"Outlier","Normal") -> Outlier | G1261: =IF(D1261<20,"<20", IF(D1261<=30,"20-30", IF(D1261<=40,"30-40","40-50"))) -> 40-50
A1262: 1261 | B1262: USA | C1262: M | D1262: 49 | E1262: C | F1262: =IF(OR(D1262>Answers!L1277,D1262<Answers!L1278),"Outlier","Normal") -> Outlier | G1262: =IF(D1262<20,"<20", IF(D1262<=30,"20-30", IF(D1262<=40,"30-40","40-50"))) -> 40-50
A1263: 1262 | B1263: USA | C1263: M | D1263: 41 | E1263: C | F1263: =IF(OR(D1263>Answers!L1278,D1263<Answers!L1279),"Outlier","Normal") -> Outlier | G1263: =IF(D1263<20,"<20", IF(D1263<=30,"20-30", IF(D1263<=40,"30-40","40-50"))) -> 40-50
A1264: 1263 | B1264: USA | C1264: F | D1264: 78 | E1264: C | F1264: =IF(OR(D1264>Answers!L1279,D1264<Answers!L1280),"Outlier","Normal") -> Outlier | G1264: =IF(D1264<20,"<20", IF(D1264<=30,"20-30", IF(D1264<=40,"30-40","40-50"))) -> 40-50
A1265: 1264 | B1265: Italy | C1265: F | D1265: 47 | E1265: C | F1265: =IF(OR(D1265>Answers!L1280,D1265<Answers!L1281),"Outlier","Normal") -> Outlier | G1265: =IF(D1265<20,"<20", IF(D1265<=30,"20-30", IF(D1265<=40,"30-40","40-50"))) -> 40-50
A1266: 1265 | B1266: USA | C1266: M | D1266: 72 | E1266: C | F1266: =IF(OR(D1266>Answers!L1281,D1266<Answers!L1282),"Outlier","Normal") -> Outlier | G1266: =IF(D1266<20,"<20", IF(D1266<=30,"20-30", IF(D1266<=40,"30-40","40-50"))) -> 40-50
A1267: 1266 | B1267: USA | C1267: M | D1267: 42 | E1267: C | F1267: =IF(OR(D1267>Answers!L1282,D1267<Answers!L1283),"Outlier","Normal") -> Outlier | G1267: =IF(D1267<20,"<20", IF(D1267<=30,"20-30", IF(D1267<=40,"30-40","40-50"))) -> 40-50
A1268: 1267 | B1268: Italy | C1268: M | D1268: 62 | E1268: C | F1268: =IF(OR(D1268>Answers!L1283,D1268<Answers!L1284),"Outlier","Normal") -> Outlier | G1268: =IF(D1268<20,"<20", IF(D1268<=30,"20-30", IF(D1268<=40,"30-40","40-50"))) -> 40-50
A1269: 1268 | B1269: USA | C1269: M | D1269: 48 | E1269: C | F1269: =IF(OR(D1269>Answers!L1284,D1269<Answers!L1285),"Outlier","Normal") -> Outlier | G1269: =IF(D1269<20,"<20", IF(D1269<=30,"20-30", IF(D1269<=40,"30-40","40-50"))) -> 40-50
A1270: 1269 | B1270: Switzerland | C1270: M | D1270: 48 | E1270: C | F1270: =IF(OR(D1270>Answers!L1285,D1270<Answers!L1286),"Outlier","Normal") -> Outlier | G1270: =IF(D1270<20,"<20", IF(D1270<=30,"20-30", IF(D1270<=40,"30-40","40-50"))) -> 40-50
A1271: 1270 | B1271: USA | C1271: M | D1271: 48 | E1271: C | F1271: =IF(OR(D1271>Answers!L1286,D1271<Answers!L1287),"Outlier","Normal") -> Outlier | G1271: =IF(D1271<20,"<20", IF(D1271<=30,"20-30", IF(D1271<=40,"30-40","40-50"))) -> 40-50
A1272: 1271 | B1272: France | C1272: F | D1272: 43 | E1272: C | F1272: =IF(OR(D1272>Answers!L1287,D1272<Answers!L1288),"Outlier","Normal") -> Outlier | G1272: =IF(D1272<20,"<20", IF(D1272<=30,"20-30", IF(D1272<=40,"30-40","40-50"))) -> 40-50
A1273: 1272 | B1273: Australia | C1273: F | D1273: 39 | E1273: C | F1273: =IF(OR(D1273>Answers!L1288,D1273<Answers!L1289),"Outlier","Normal") -> Outlier | G1273: =IF(D1273<20,"<20", IF(D1273<=30,"20-30", IF(D1273<=40,"30-40","40-50"))) -> 30-40
... A1497: 1496 | B1497: USA | C1497: F | D1497: 74 | E1497: C | F1497: =IF(OR(D1497>Answers!L1512,D1497<Answers!L1513),"Outlier","Normal") -> Outlier | G1497: =IF(D1497<20,"<20", IF(D1497<=30,"20-30", IF(D1497<=40,"30-40","40-50"))) -> 40-50
A1498: 1497 | B1498: Spain | C1498: F | D1498: =ROUND(AVERAGE(D1495:D1497),0) -> 48 | E1498: C | F1498: =IF(OR(D1498>Answers!L1513,D1498<Answers!L1514),"Outlier","Normal") -> Outlier | G1498: =IF(D1498<20,"<20", IF(D1498<=30,"20-30", IF(D1498<=40,"30-40","40-50"))) -> 40-50
A1499: 1498 | B1499: Germany | C1499: F | D1499: 75 | E1499: C | F1499: =IF(OR(D1499>Answers!L1514,D1499<Answers!L1515),"Outlier","Normal") -> Outlier | G1499: =IF(D1499<20,"<20", IF(D1499<=30,"20-30", IF(D1499<=40,"30-40","40-50"))) -> 40-50
A1500: 1499 | B1500: USA | C1500: F | D1500: 48 | E1500: C | F1500: =IF(OR(D1500>Answers!L1515,D1500<Answers!L1516),"Outlier","Normal") -> Outlier | G1500: =IF(D1500<20,"<20", IF(D1500<=30,"20-30", IF(D1500<=40,"30-40","40-50"))) -> 40-50
A1501: 1500 | B1501: USA | C1501: M | D1501: 19 | E1501: C | F1501: =IF(OR(D1501>Answers!L1516,D1501<Answers!L1517),"Outlier","Normal") -> Outlier | G1501: =IF(D1501<20,"<20", IF(D1501<=30,"20-30", IF(D1501<=40,"30-40","40-50"))) -> <20
A1502: 1501 | B1502: USA | C1502: M | D1502: 51 | E1502: D | F1502: =IF(OR(D1502>Answers!L1517,D1502<Answers!L1518),"Outlier","Normal") -> Outlier | G1502: =IF(D1502<20,"<20", IF(D1502<=30,"20-30", IF(D1502<=40,"30-40","40-50"))) -> 40-50
A1503: 1502 | B1503: Spain | C1503: F | D1503: 33 | E1503: D | F1503: =IF(OR(D1503>Answers!L1518,D1503<Answers!L1519),"Outlier","Normal") -> Outlier | G1503: =IF(D1503<20,"<20", IF(D1503<=30,"20-30", IF(D1503<=40,"30-40","40-50"))) -> 30-40
A1504: 1503 | B1504: Norway | C1504: F | D1504: 79 | E1504: D | F1504: =IF(OR(D1504>Answers!L1519,D1504<Answers!L1520),"Outlier","Normal") -> Outlier | G1504: =IF(D1504<20,"<20", IF(D1504<=30,"20-30", IF(D1504<=40,"30-40","40-50"))) -> 40-50
A1505: 1504 | B1505: France | C1505: F | D1505: 33 | E1505: D | F1505: =IF(OR(D1505>Answers!L1520,D1505<Answers!L1521),"Outlier","Normal") -> Outlier | G1505: =IF(D1505<20,"<20", IF(D1505<=30,"20-30", IF(D1505<=40,"30-40","40-50"))) -> 30-40
...

Sheet Sales Targets
A1: Sales POC | B1: Sales Manager Full Name | C1: Sales Team | D1: 2023 Sales Target | E1: Achieved Sales | F1: Target Status
A2: Diego Freyre | B2: Noah Meier | C2: Alpha | D2: 1000000 | E2: =SUMIFS(Orders!G:G,Orders!F:F,A2) -> 1089868 | F2: =IF(E2<D2,"Target Not Met",IF(E2=D2,"Target Met","Exceeded Target")) -> Exceeded Target
A3: Valarie Nelson | B3: Benjamin Chen | C3: Delta | D3: 1000000 | E3: =SUMIFS(Orders!G:G,Orders!F:F,A3) -> 776835 | F3: =IF(E3<D3,"Target Not Met",IF(E3=D3,"Target Met","Exceeded Target")) -> Target Not Met
A4: Victoria Ashworth | B4: Ethan Lee | C4: Beta | D4: 250000 | E4: =SUMIFS(Orders!G:G,Orders!F:F,A4) -> 261093 | F4: =IF(E4<D4,"Target Not Met",IF(E4=D4,"Target Met","Exceeded Target")) -> Exceeded Target
A5: Wendy Victorino | B5: Benjamin Weber | C5: Epsilon | D5: 250000 | E5: =SUMIFS(Orders!G:G,Orders!F:F,A5) -> 171694 | F5: =IF(E5<D5,"Target Not Met",IF(E5=D5,"Target Met","Exceeded Target")) -> Target Not Met
A6: Peter Ferguson | B6: Marco Bianchi | C6: Alpha | D6: 250000 | E6: =SUMIFS(Orders!G:G,Orders!F:F,A6) -> 261772 | F6: =IF(E6<D6,"Target Not Met",IF(E6=D6,"Target Met","Exceeded Target")) -> Exceeded Target
A7: Julie Brown | B7: Lukas Schmidt | C7: Alpha | D7: 200000 | E7: =SUMIFS(Orders!G:G,Orders!F:F,A7) -> 192740 | F7: =IF(E7<D7,"Target Not Met",IF(E7=D7,"Target Met","Exceeded Target")) -> Target Not Met
A8: Jeff Young | B8: Olivia Jensen | C8: Beta | D8: 200000 | E8: =SUMIFS(Orders!G:G,Orders!F:F,A8) -> 227134 | F8: =IF(E8<D8,"Target Not Met",IF(E8=D8,"Target Met","Exceeded Target")) -> Exceeded Target
A9: Adrian Huxley | B9: Chloe Dupont | C9: Beta | D9: 200000 | E9: =SUMIFS(Orders!G:G,Orders!F:F,A9) -> 182094 | F9: =IF(E9<D9,"Target Not Met",IF(E9=D9,"Target Met","Exceeded Target")) -> Target Not Met | I9: Steve Frick's target and achieved sales.
A10: Kwai Yu | B10: Alexander Müller | C10: Alpha | D10: 200000 | E10: =SUMIFS(Orders!G:G,Orders!F:F,A10) -> 219735 | F10: =IF(E10<D10,"Target Not Met",IF(E10=D10,"Target Met","Exceeded Target")) -> Exceeded Target | I10: =INDEX(D:D, MATCH("Steve Frick", A:A, 0)) -> 100000 | K10: =INDEX(E:E, MATCH("Steve Frick", A:A, 0)) -> 98119
A11: Paul Henriot | B11: Sophia Rossi | C11: Beta | D11: 200000 | E11: =SUMIFS(Orders!G:G,Orders!F:F,A11) -> 195983 | F11: =IF(E11<D11,"Target Not Met",IF(E11=D11,"Target Met","Exceeded Target")) -> Target Not Met | I11: Target | K11: Achieved
A12: Anna O'Hara | B12: Isabella Garcia | C12: Alpha | D12: 200000 | E12: =SUMIFS(Orders!G:G,Orders!F:F,A12) -> 242439 | F12: =IF(E12<D12,"Target Not Met",IF(E12=D12,"Target Met","Exceeded Target")) -> Exceeded Target
A13: Janine Labrune | B13: Dev Patel | C13: Delta | D13: 200000 | E13: =SUMIFS(Orders!G:G,Orders!F:F,A13) -> 203887 | F13: =IF(E13<D13,"Target Not Met",IF(E13=D13,"Target Met","Exceeded Target")) -> Exceeded Target
A14: Eric Natividad | B14: Daniela Hernandez | C14: Gamma | D14: 200000 | E14: =SUMIFS(Orders!G:G,Orders!F:F,A14) -> 201398 | F14: =IF(E14<D14,"Target Not Met",IF(E14=D14,"Target Met","Exceeded Target")) -> Exceeded Target | I14: Team of Dean Cassidy | L14: If he met the target
A15: Kee Kuo | B15: Liam O'Sullivan | C15: Beta | D15: 200000 | E15: =SUMIFS(Orders!G:G,Orders!F:F,A15) -> 63116 | F15: =IF(E15<D15,"Target Not Met",IF(E15=D15,"Target Met","Exceeded Target")) -> Target Not Met | I15: =INDEX(C:C, MATCH("Dean Cassidy", A:A, 0)) -> Beta | L15: =INDEX(F:F, MATCH("Dean Cassidy", A:A, 0)) -> Exceeded Target
A16: Sue Frick | B16: Benjamin Weber | C16: Epsilon | D16: 200000 | E16: =SUMIFS(Orders!G:G,Orders!F:F,A16) -> 195359 | F16: =IF(E16<D16,"Target Not Met",IF(E16=D16,"Target Met","Exceeded Target")) -> Target Not Met
A17: Mary Saveley | B17: Lucas Nielsen | C17: Gamma | D17: 150000 | E17: =SUMIFS(Orders!G:G,Orders!F:F,A17) -> 173391 | F17: =IF(E17<D17,"Target Not Met",IF(E17=D17,"Target Met","Exceeded Target")) -> Exceeded Target
A18: Henriette Pfalzheim | B18: Aino Virtanen | C18: Beta | D18: 150000 | E18: =SUMIFS(Orders!G:G,Orders!F:F,A18) -> 145237 | F18: =IF(E18<D18,"Target Not Met",IF(E18=D18,"Target Met","Exceeded Target")) -> Target Not Met
A19: Laurence Lebihan | B19: Emily Dubois | C19: Delta | D19: 150000 | E19: =SUMIFS(Orders!G:G,Orders!F:F,A19) -> 115291 | F19: =IF(E19<D19,"Target Not Met",IF(E19=D19,"Target Met","Exceeded Target")) -> Target Not Met
A20: Giovanni Rovelli | B20: Emily Murphy | C20: Alpha | D20: 150000 | E20: =SUMIFS(Orders!G:G,Orders!F:F,A20) -> 175816 | F20: =IF(E20<D20,"Target Not Met",IF(E20=D20,"Target Met","Exceeded Target")) -> Exceeded Target
A21: Paolo Accorti | B21: Marco Bianchi | C21: Alpha | D21: 150000 | E21: =SUMIFS(Orders!G:G,Orders!F:F,A21) -> 137504 | F21: =IF(E21<D21,"Target Not Met",IF(E21=D21,"Target Met","Exceeded Target")) -> Target Not Met
A22: Marie Bertrand | B22: Charlotte Miller | C22: Gamma | D22: 150000 | E22: =SUMIFS(Orders!G:G,Orders!F:F,A22) -> 125181 | F22: =IF(E22<D22,"Target Not Met",IF(E22=D22,"Target Met","Exceeded Target")) -> Target Not Met
A23: Georg Pipps | B23: Priya Kapoor | C23: Alpha | D23: 150000 | E23: =SUMIFS(Orders!G:G,Orders!F:F,A23) -> 188709 | F23: =IF(E23<D23,"Target Not Met",IF(E23=D23,"Target Met","Exceeded Target")) -> Exceeded Target
A24: Juri Hirano | B24: Sofia Laine | C24: Gamma | D24: 150000 | E24: =SUMIFS(Orders!G:G,Orders!F:F,A24) -> 167417 | F24: =IF(E24<D24,"Target Not Met",IF(E24=D24,"Target Met","Exceeded Target")) -> Exceeded Target
A25: Mart¡n Sommer | B25: Chloe Dupont | C25: Beta | D25: 150000 | E25: =SUMIFS(Orders!G:G,Orders!F:F,A25) -> 139565 | F25: =IF(E25<D25,"Target Not Met",IF(E25=D25,"Target Met","Exceeded Target")) -> Target Not Met
A26: Dominique Perrier | B26: Liam O'Sullivan | C26: Beta | D26: 150000 | E26: =SUMIFS(Orders!G:G,Orders!F:F,A26) -> 143869 | F26: =IF(E26<D26,"Target Not Met",IF(E26=D26,"Target Met","Exceeded Target")) -> Target Not Met
A27: Michael Frick | B27: Sophia Rossi | C27: Beta | D27: 150000 | E27: =SUMIFS(Orders!G:G,Orders!F:F,A27) -> 123241 | F27: =IF(E27<D27,"Target Not Met",IF(E27=D27,"Target Met","Exceeded Target")) -> Target Not Met
... A82: Maria Hernandez | B82: Oliver Kumar | C82: Beta | D82: 80000 | E82: =SUMIFS(Orders!G:G,Orders!F:F,A82) -> 70369 | F82: =IF(E82<D82,"Target Not Met",IF(E82=D82,"Target Met","Exceeded Target")) -> Target Not Met
A83: Thomas Hardy | B83: Mia Khan | C83: Epsilon | D83: 50000 | E83: =SUMIFS(Orders!G:G,Orders!F:F,A83) -> 49487 | F83: =IF(E83<D83,"Target Not Met",IF(E83=D83,"Target Met","Exceeded Target")) -> Target Not Met | H83: 6016306
A84: Dean Cassidy | B84: Oliver Kumar | C84: Beta | D84: 50000 | E84: =SUMIFS(Orders!G:G,Orders!F:F,A84) -> 57084 | F84: =IF(E84<D84,"Target Not Met",IF(E84=D84,"Target Met","Exceeded Target")) -> Exceeded Target
A85: Eduardo Saavedra | B85: Emily Murphy | C85: Alpha | D85: 50000 | E85: =SUMIFS(Orders!G:G,Orders!F:F,A85) -> 45184 | F85: =IF(E85<D85,"Target Not Met",IF(E85=D85,"Target Met","Exceeded Target")) -> Target Not Met
A86: Pascale Cartrain | B86: Olivia Jensen | C86: Beta | D86: 50000 | E86: =SUMIFS(Orders!G:G,Orders!F:F,A86) -> 44651 | F86: =IF(E86<D86,"Target Not Met",IF(E86=D86,"Target Met","Exceeded Target")) -> Target Not Met
A87: Miguel Barajas | B87: Liam Baumann | C87: Beta | D87: 50000 | E87: =SUMIFS(Orders!G:G,Orders!F:F,A87) -> 51911 | F87: =IF(E87<D87,"Target Not Met",IF(E87=D87,"Target Met","Exceeded Target")) -> Exceeded Target
A88: Jesus Fernandez | B88: Ava Williams | C88: Epsilon | D88: 50000 | E88: =SUMIFS(Orders!G:G,Orders!F:F,A88) -> 41950 | F88: =IF(E88<D88,"Target Not Met",IF(E88=D88,"Target Met","Exceeded Target")) -> Target Not Met
A89: Leslie Taylor | B89: Ethan Lee | C89: Beta | D89: 30000 | E89: =SUMIFS(Orders!G:G,Orders!F:F,A89) -> 25048 | F89: =IF(E89<D89,"Target Not Met",IF(E89=D89,"Target Met","Exceeded Target")) -> Target Not Met
A90: Michael Donnermeyer | B90: Mia Khan | C90: Epsilon | D90: 30000 | E90: =SUMIFS(Orders!G:G,Orders!F:F,A90) -> 31897 | F90: =IF(E90<D90,"Target Not Met",IF(E90=D90,"Target Met","Exceeded Target")) -> Exceeded Target
A91: Leslie Young | B91: Sofia Laine | C91: Gamma | D91: 30000 | E91: =SUMIFS(Orders!G:G,Orders!F:F,A91) -> 10197 | F91: =IF(E91<D91,"Target Not Met",IF(E91=D91,"Target Met","Exceeded Target")) -> Target Not Met
A92: Carine Schmitt | B92: Aino Virtanen | C92: Beta | D92: 30000 | E92: =SUMIFS(Orders!G:G,Orders!F:F,A92) -> 38017 | F92: =IF(E92<D92,"Target Not Met",IF(E92=D92,"Target Met","Exceeded Target")) -> Exceeded Target
A93: Dan Lewis | B93: Emily Dubois | C93: Delta | D93: 30000 | E93: =SUMIFS(Orders!G:G,Orders!F:F,A93) -> 42553 | F93: =IF(E93<D93,"Target Not Met",IF(E93=D93,"Target Met","Exceeded Target")) -> Exceeded Target

Sheet Answers
B2: =COUNTBLANK(Orders!C2:C2501) -> 0 | C2: =COUNTBLANK(Customers!D2:D2501) -> 0
B3: =COUNTA(Orders!C2:C2501) -> 2500
B4: =B3-B2 -> 2500
B6: Row Labels | C6: Count of Customer Country | E6: Row Labels | F6: Count of Order Source | H6: 1 | I6: cleaned blank values from customer country and order sources
B7: USA | C7: 885 | E7: Website | F7: 637 | H7: 2 | I7: cleaned blank values in the customer age column using moving average
B8: France | C8: 323 | E8: Whatsapp | F8: 633
B9: India | C9: 281 | E9: App | F9: 622
B10: Spain | C10: 268 | E10: Other | F10: 591
B11: Australia | C11: 198
B12: Italy | C12: 112 | H12: Order Value | K12: Age
B13: Singapore | C13: 97 | H13: q1 | I13: =QUARTILE(Orders!G2:G2501,1) -> 2364 | K13: q1 | L13: =QUARTILE(Customers!D2:D2501,1) -> 36
B14: Denmark | C14: 66 | H14: q3 | I14: =QUARTILE(Orders!G2:G2501,3) -> 7439.25 | K14: q3 | L14: =QUARTILE(Customers!D2:D2501,3) -> 72
B15: Finland | C15: 66 | H15: iqr | I15: =I14-I13 -> 5075.25 | K15: iqr | L15: =L14-L13 -> 36
B16: Germany | C16: 58
B17: Austria | C17: 43 | H17: Upper Limit | I17: =I14+(1.5*I15) -> 15052.125 | K17: Upper Limit | L17: =L14+(1.5*L15) -> 126
B18: Norway | C18: 40 | H18: Lower Limit | I18: =I13-(1.5*I15) -> -5248.875 | K18: Lower Limit | L18: =L13-(1.5*L15) -> -18
B19: Switzerland | C19: 36
B20: Ireland | C20: 20
B22: =INDEX(Orders!C2:C2501,MODE(MATCH(Orders!C2:C2501,Orders!C2:C2501,0))) -> USA | C22: INDEX(Orders!C2:C2501,MODE(MATCH(Orders!C2:C2501,Orders!C2:C2501,0))) | J22: =SUMPRODUCT((MONTH(DATEVALUE("1 "&Orders!J2:J2501))>=7)*Orders!G2:G2501) -> 6095203 | K22: using sumproduct
C23: ROUND(AVERAGE(D2:D4),0) | J23: =SUMPRODUCT(--(MONTH(DATEVALUE("1 "&Orders!J2:J2501))>=7)) -> 1249 | K23: using sumproduct
J26: =SUMIFS(Orders!G2:G2501,Orders!H2:H2501,">="&DATE(2023,7,1)) -> 6095203 | K26: Total sales value in the second half of the year.
J27: =COUNTIFS(Orders!H2:H2501,">="&DATE(2023,7,1)) -> 1249 | K27: Number of orders placed in the second half of the year.
J29: =SUMIFS(Orders!G2:G2501,Orders!C2:C2501,"India") -> 1356737 | K29: Indian customers sales
J30: =COUNTIF(Orders!C2:C2501,"India") -> 281 | K30: Indian customers orders
J32: =AVERAGEIFS(Orders!G:G,Orders!E:E,"Whatsapp") -> 4760.8231 | K32: Whatsapp order average
J33: =COUNTIFS(Orders!H:H,">="&DATE(2023,6,15),Customers!D:D,">30") -> 1131 | K33: Orders after 15 June & age >30

Sheet OBJS
A3: Row Labels | B3: Count of Order ID | C3: Average of Order Value
A4: January | B4: 217 | C4: 4854.4286
A5: February | B5: 220 | C5: 4979.5909
A6: March | B6: 197 | C6: 5166.2234
A7: April | B7: 197 | C7: 4822.2335
A8: May | B8: 207 | C8: 4901.6425
A9: June | B9: 213 | C9: 4926.7606
A10: July | B10: 209 | C10: 4989.1962
A11: August | B11: 207 | C11: 5169.5797
A12: September | B12: 195 | C12: 4759.041
A13: October | B13: 201 | C13: 4673.4925
A14: November | B14: 229 | C14: 5236.1092
A15: December | B15: 208 | C15: 4403.3846
A16: Grand Total | B16: 2500 | C16: 4910.356
A20: Row Labels | B20: Count of Customer ID | C20: Sum of Order Value
A21: USA | B21: 892 | C21: 4295296
A22: France | B22: 323 | C22: 1637659
A23: Spain | B23: 268 | C23: 1378166
A24: India | B24: 281 | C24: 1356737
A25: Australia | B25: 198 | C25: 974217
A26: Italy | B26: 112 | C26: 538932
A27: Singapore | B27: 97 | C27: 486633
A28: Finland | B28: 66 | C28: 324319
A29: Denmark | B29: 66 | C29: 307260
A30: Germany | B30: 58 | C30: 299656
A31: Austria | B31: 43 | C31: 223916
A32: Norway | B32: 40 | C32: 195229
... A35: Grand Total | B35: 2500 | C35: 12275890
A39: Row Labels | B39: Count of Customer ID | C39: Average of Order Value
A40: 16 | B40: 2 | C40: 6297.5
A41: 00 | B41: 1005 | C41: 4984.1632
A42: 01 | B42: 629 | C42: 4969.4308
A43: 22 | B43: 156 | C43: 4933.6026
A44: 23 | B44: 648 | C44: 4760.4429
A45: 02 | B45: 58 | C45: 4571.431
A46: 14 | B46: 2 | C46: 4443.5
A47: Grand Total | B47: 2500 | C47: 4910.356
A54: Row Labels | B54: Count of Customer ID
A55: 40-50 | B55: 1702
A56: 20-30 | B56: 375
...
